Workbook

Sheet 📋 Instructions
B2: WESTEROS CASTLE DATA COLLECTION
B3: Data collection guide for the GoT Neptune's Pride game
B6: YOUR JOB
B7: Step 1 | C7: Go to the 🏰 Castle Data sheet
B8: Step 2 | C8: Find a castle row with Status = STUB (highlighted red)
B9: Step 3 | C9: Visit the wiki URL in column W for that castle
B10: Step 4 | C10: Fill in as many columns as you can from the wiki page
B11: Step 5 | C11: Change Status in column A to PARTIAL or COMPLETE when done
B12: Step 6 | C12: Move to the next STUB row and repeat
B14: COLUMN GUIDE
B15: slug | C15: Auto-filled. Don't edit.
B16: name | C16: Auto-filled. Don't edit.
B17: region | C17: Auto-filled. Don't edit.
B18: tier | C18: Auto-filled. Don't edit.
B19: status | C19: Change to PARTIAL when you start, COMPLETE when done.
B20: connections | C20: Castles nearby on the wiki map. Comma-separated castle names. Look at the infobox map image on each wiki page and list what's adjacent.
B21: route_type | C21: land, sea, or both — based on whether the castle is coastal/island
B22: gold | C22: How wealthy/economically important is this castle? Rate 1-10. Use tier as guide: T1=7-10, T2=4-6, T3=1-3
B23: strength | C23: How militarily significant? Same 1-10 scale.
B24: influence | C24: How politically/intellectually important? T1=5-8, T2=2-4, T3=0-1
B25: natural_resources | C25: How easy to develop? Rich areas score higher. T1=7-10, T2=4-7, T3=1-4
B26: defense_bonus | C26: How naturally defensible? Mountains/islands score highest (4-5). Plains lowest (1).
... B37: your_name | C37: Put your name/initials so we know who collected each entry.
B39: TIER GUIDE
B40: Tier 1 | C40: Great Seats — Winterfell, Casterly Rock, Highgarden, Red Keep, Dragonstone, Storm's End, Eyrie, Riverrun, Harrenhal, Twins, Moat Cailin, Pyke, Sunspear, Hightower
B41: Tier 2 | C41: Named house seats with regional importance. Lords and notable knights.
B42: Tier 3 | C42: Minor holdfasts, towers, small keeps. Background territory.
B44: TIPS
B45: Wiki URL format | C45: https://awoiaf.westeros.org/index.php/Castle_Name (spaces become underscores)
B46: Connections | C46: The small regional MAP on each wiki page is your best friend for adjacency. List 2-5 nearby castles per entry.
B47: When unsure | C47: Leave blank rather than guess. PARTIAL is fine. We can fill gaps later.
B48: Sea routes | C48: Iron Islands castles are all island/sea. Coastal castles (Dragonstone, Pyke, Sunspear, Hightower) can have both land and sea connections.

Sheet 🏰 Castle Data
A1: META | C1: IDENTITY | G1: CONNECTIONS | K1: BASE STATS | P1: SPECIAL | V1: LORE
A2: status | B2: collected_by | C2: slug | D2: name | E2: region | F2: tier | G2: connections | H2: route_types | I2: distance_ticks_notes | J2: is_kings_road | K2: gold | L2: strength | M2: influence | N2: natural_resources | O2: defense_bonus | P2: is_port | Q2: is_chokepoint | R2: has_maester | S2: terrain | T2: winter_mult | U2: unique_bonus | V2: ruling_house | W2: current_ruler | X2: religion | Y2: description | Z2: notable_events | AA2: wiki_url
A3: PARTIAL | B3: Claude | C3: red_keep | D3: Red Keep | E3: Crownlands | F3: 1 | G3: King's Landing, Rook's Rest, Rosby | H3: land, sea | I3: 0 | J3: YES | K3: 5 | L3: 5 | M3: 4 | N3: 7 | O3: 3 | P3: YES | Q3: NO | R3: YES | S3: coast | T3: 1 | U3: Capital: Royal treasury access | V3: house_baratheon_kings_landing | W3: Robert Baratheon | X3: faith_of_the_seven | Y3: The royal seat of the Seven Kingdoms, located in King's Landing on the Blackwater Rush. Ancient fortress and center of Iron Throne power. | Z3: Targaryen construction, Mad King's reign, Robert's Rebellion, Dance of Dragons precedent | AA3: https://awoiaf.westeros.org/index.php/Red_Keep
A4: PARTIAL | B4: Claude | C4: dragonstone | D4: Dragonstone | E4: Crownlands | F4: 1 | G4: Claw Isle, Driftmark | H4: sea | I4: 2 | J4: NO | K4: 5 | L4: 5 | M4: 4 | N4: 7 | O4: 3 | P4: YES | Q4: NO | R4: YES | S4: island | T4: 1 | U4: Volcanic fortress: +1 defense | V4: house_targaryen | W4: Daenerys Targaryen | X4: rhlor | Y4: Fortress on volcanic island east of King's Landing. Stronghold of House Targaryen and seat of Stannis Baratheon. Gateway to the Narrow Sea. | Z4: Targaryen ancestral seat, Stannis's rule, volcanic origin | AA4: https://awoiaf.westeros.org/index.php/Dragonstone
A5: PARTIAL | B5: Claude | C5: rosby | D5: Rosby | E5: Crownlands | F5: 2 | G5: Red Keep, Stokeworth, Rook's Rest | H5: land | I5: 1-3 | J5: NO | K5: 3 | L5: 3 | M5: 2 | N5: 5 | O5: 2 | P5: NO | Q5: NO | R5: NO | S5: plains | T5: 1 | V5: house_rosby | W5: Unknown | X5: faith_of_the_seven | Y5: Crownlands castle near King's Landing. | Z5: None major | AA5: https://awoiaf.westeros.org/index.php/Rosby
A6: PARTIAL | B6: Claude | C6: stokeworth | D6: Stokeworth | E6: Crownlands | F6: 2 | G6: Red Keep, Rosby, Rook's Rest | H6: land | I6: 1-3 | J6: NO | K6: 3 | L6: 3 | M6: 2 | N6: 5 | O6: 2 | P6: NO | Q6: NO | R6: NO | S6: plains | T6: 1 | V6: house_stokeworth | W6: Unknown | X6: faith_of_the_seven | Y6: Minor Crownlands castle. | Z6: None major | AA6: https://awoiaf.westeros.org/index.php/Stokeworth
A7: PARTIAL | B7: Claude | C7: rooks_rest | D7: Rook's Rest | E7: Crownlands | F7: 2 | G7: Red Keep, Rosby, Stokeworth | H7: land | I7: 1-3 | J7: NO | K7: 3 | L7: 3 | M7: 2 | N7: 5 | O7: 2 | P7: NO | Q7: NO | R7: NO | S7: plains | T7: 1 | V7: unknown | W7: Unknown | X7: faith_of_the_seven | Y7: Crownlands castle south of King's Landing. | Z7: Strategic position | AA7: https://awoiaf.westeros.org/index.php/Rooks_Rest
A8: PARTIAL | B8: Claude | C8: driftmark | D8: Castle Driftmark | E8: Crownlands | F8: 2 | G8: Dragonstone, Claw Isle, Red Keep (sea) | H8: sea | I8: 1-3 | J8: NO | K8: 3 | L8: 3 | M8: 2 | N8: 5 | O8: 2 | P8: YES | Q8: NO | R8: NO | S8: island | T8: 1 | V8: house_velaryon | W8: Monterys Velaryon | X8: faith_of_the_seven | Y8: Island castle of House Velaryon. | Z8: Naval stronghold | AA8: https://awoiaf.westeros.org/index.php/Driftmark
A9: PARTIAL | B9: Claude | C9: sharp_point | D9: Sharp Point | E9: Crownlands | F9: 3 | G9: Red Keep (sea), Driftmark (sea) | H9: sea | I9: 1-3 | J9: NO | K9: 1 | L9: 1 | M9: 0 | N9: 3 | O9: 1 | P9: YES | Q9: NO | R9: NO | S9: coast | T9: 1 | V9: house_bar_emmon | W9: Unknown | X9: faith_of_the_seven | Y9: Coastal Crownlands fortress. | Z9: Harbor fortress | AA9: https://awoiaf.westeros.org/index.php/Sharp_Point
A10: PARTIAL | B10: Claude | C10: sweetport_sound | D10: Sweetport Sound | E10: Crownlands | F10: 3 | G10: Sharp Point (sea) | H10: sea | I10: 1-3 | J10: NO | K10: 1 | L10: 1 | M10: 0 | N10: 3 | O10: 1 | P10: YES | Q10: NO | R10: NO | S10: coast | T10: 1 | V10: house_sunglass | W10: Unknown | X10: faith_of_the_seven | Y10: Coastal Crownlands fortress. | Z10: Trade port | AA10: https://awoiaf.westeros.org/index.php/Sweetport_Sound
A11: PARTIAL | B11: Claude | C11: stonedance | D11: Stonedance | E11: Crownlands | F11: 3 | G11: Red Keep (sea) | H11: sea | I11: 1-3 | J11: NO | K11: 1 | L11: 1 | M11: 0 | N11: 3 | O11: 1 | P11: YES | Q11: NO | R11: NO | S11: coast | T11: 1 | V11: house_massey | W11: Unknown | X11: faith_of_the_seven | Y11: Coastal Crownlands castle. | Z11: Coastal stronghold | AA11: https://awoiaf.westeros.org/index.php/Stonedance
A12: PARTIAL | B12: Claude | C12: antlers | D12: Antlers | E12: Crownlands | F12: 3 | G12: Red Keep, Rosby | H12: land | I12: 1-3 | J12: NO | K12: 1 | L12: 1 | M12: 0 | N12: 3 | O12: 1 | P12: NO | Q12: NO | R12: NO | S12: forest | T12: 1 | V12: unknown | W12: Unknown | X12: faith_of_the_seven | Y12: Forest stronghold near King's Landing. | Z12: None major | AA12: https://awoiaf.westeros.org/index.php/Antlers
A13: PARTIAL | B13: Claude | C13: brownhollow | D13: Brownhollow | E13: Crownlands | F13: 3 | G13: Red Keep, Rosby | H13: land | I13: 1-3 | J13: NO | K13: 1 | L13: 1 | M13: 0 | N13: 3 | O13: 1 | P13: NO | Q13: NO | R13: NO | S13: plains | T13: 1 | V13: unknown | W13: Unknown | X13: faith_of_the_seven | Y13: Minor Crownlands stronghold. | Z13: None major | AA13: https://awoiaf.westeros.org/index.php/Brownhollow
A14: PARTIAL | B14: Claude | C14: breakwater | D14: Breakwater | E14: Crownlands | F14: 3 | G14: Red Keep (sea) | H14: sea | I14: 1-3 | J14: NO | K14: 1 | L14: 1 | M14: 0 | N14: 3 | O14: 1 | P14: YES | Q14: NO | R14: NO | S14: coast | T14: 1 | V14: unknown | W14: Unknown | X14: faith_of_the_seven | Y14: Coastal Crownlands fortress. | Z14: Naval station | AA14: https://awoiaf.westeros.org/index.php/Breakwater
A15: PARTIAL | B15: Claude | C15: ravenry | D15: Ravenry | E15: Crownlands | F15: 3 | G15: Red Keep | H15: land | I15: 1-3 | J15: NO | K15: 1 | L15: 1 | M15: 0 | N15: 3 | O15: 1 | P15: NO | Q15: NO | R15: NO | S15: forest | T15: 1 | V15: unknown | W15: Unknown | X15: faith_of_the_seven | Y15: Small Crownlands fortress. | Z15: None major | AA15: https://awoiaf.westeros.org/index.php/Ravenry
A16: PARTIAL | B16: Claude | C16: high_tide | D16: High Tide | E16: Crownlands | F16: 3 | G16: Driftmark (sea) | H16: sea | I16: 1-3 | J16: NO | K16: 1 | L16: 1 | M16: 0 | N16: 3 | O16: 1 | P16: YES | Q16: NO | R16: NO | S16: coast | T16: 1 | V16: unknown | W16: Unknown | X16: faith_of_the_seven | Y16: Coastal Crownlands castle. | Z16: Tidal harbor | AA16: https://awoiaf.westeros.org/index.php/High_Tide
... A18: PARTIAL | B18: Claude | C18: ring | D18: Ring | E18: Crownlands | F18: 3 | G18: Red Keep | H18: land | I18: 1-3 | J18: NO | K18: 1 | L18: 1 | M18: 0 | N18: 3 | O18: 1 | P18: NO | Q18: NO | R18: NO | S18: plains | T18: 1 | V18: unknown | W18: Unknown | X18: faith_of_the_seven | Y18: Small circular fortress. | Z18: None major | AA18: https://awoiaf.westeros.org/index.php/Ring
A19: PARTIAL | B19: Claude | C19: winterfell | D19: Winterfell | E19: North | F19: 1 | G19: Moat Cailin, Last Hearth, Castle Cerwyn, Deepwood Motte | H19: land | I19: 4 | J19: YES | K19: 5 | L19: 5 | M19: 4 | N19: 7 | O19: 3 | P19: NO | Q19: NO | R19: YES | S19: forest | T19: 1.5 | U19: Hot springs: winter immunity | V19: house_stark | W19: Ned Stark | X19: old_gods | Y19: Ancestral castle and capital of the North, seat of House Stark. Built by Bran the Builder atop hot springs that warm it even in winter. | Z19: Founded by Bran the Builder, Robert's Rebellion, War of Five Kings | AA19: https://awoiaf.westeros.org/index.php/Winterfell
A20: PARTIAL | B20: Claude | C20: moat_cailin | D20: Moat Cailin | E20: North | F20: 1 | G20: Winterfell, The Twins, Last Hearth | H20: land | I20: 3 | J20: NO | K20: 5 | L20: 5 | M20: 4 | N20: 7 | O20: 3 | P20: YES | Q20: YES | R20: NO | S20: swamp | T20: 1.5 | U20: Swamp fortress: march speed halved | V20: house_stark | W20: Unknown | X20: old_gods | Y20: Strategic fortress in the Neck controlling entry from south to the North. Three towers and flooded defenses make it nearly impregnable from south. | Z20: Repelled Andal invasion, War of Five Kings | AA20: https://awoiaf.westeros.org/index.php/Moat_Cailin
A21: PARTIAL | B21: Claude | C21: dreadfort | D21: Dreadfort | E21: North | F21: 2 | G21: Winterfell, Karhold, Last Hearth | H21: land | I21: 1-3 | J21: NO | K21: 3 | L21: 3 | M21: 2 | N21: 5 | O21: 2 | P21: NO | Q21: NO | R21: NO | S21: forest | T21: 1.5 | V21: house_bolton | W21: Roose Bolton | X21: old_gods | Y21: Grim Northern fortress. | Z21: Flaying tradition | AA21: https://awoiaf.westeros.org/index.php/Dreadfort
A22: PARTIAL | B22: Claude | C22: karhold | D22: Karhold | E22: North | F22: 2 | G22: Dreadfort, Last Hearth, Castle Cerwyn | H22: land | I22: 1-3 | J22: NO | K22: 3 | L22: 3 | M22: 2 | N22: 5 | O22: 2 | P22: NO | Q22: NO | R22: NO | S22: mountains | T22: 1.5 | V22: house_karstark | W22: Rickard Karstark | X22: old_gods | Y22: Mountain Northern fortress. | Z22: Mountain stronghold | AA22: https://awoiaf.westeros.org/index.php/Karhold
A23: PARTIAL | B23: Claude | C23: castle_cerwyn | D23: Castle Cerwyn | E23: North | F23: 2 | G23: Winterfell, Karhold, Torrhen's Square | H23: land | I23: 1-3 | J23: NO | K23: 3 | L23: 3 | M23: 2 | N23: 5 | O23: 2 | P23: NO | Q23: NO | R23: NO | S23: forest | T23: 1.5 | V23: house_cerwyn | W23: Cley Cerwyn | X23: old_gods | Y23: Northern forest fortress. | Z23: Southern gateway | AA23: https://awoiaf.westeros.org/index.php/Castle_Cerwyn
A24: PARTIAL | B24: Claude | C24: hornwood | D24: Hornwood | E24: North | F24: 2 | G24: Winterfell, Dreadfort, Deepwood Motte | H24: land | I24: 1-3 | J24: NO | K24: 3 | L24: 3 | M24: 2 | N24: 5 | O24: 2 | P24: NO | Q24: NO | R24: NO | S24: forest | T24: 1.5 | V24: house_hornwood | W24: Daryn Hornwood | X24: old_gods | Y24: Forest Northern fortress. | Z24: Disputed succession | AA24: https://awoiaf.westeros.org/index.php/Hornwood
A25: PARTIAL | B25: Claude | C25: barrow_hall | D25: Barrow Hall | E25: North | F25: 2 | G25: Winterfell, Castle Cerwyn | H25: land | I25: 1-3 | J25: NO | K25: 3 | L25: 3 | M25: 2 | N25: 5 | O25: 2 | P25: NO | Q25: NO | R25: NO | S25: plains | T25: 1.5 | V25: house_dustin | W25: Barbrey Dustin | X25: old_gods | Y25: Northern plains fortress. | Z25: Horse breeding | AA25: https://awoiaf.westeros.org/index.php/Barrow_Hall
A26: PARTIAL | B26: Claude | C26: deepwood_motte | D26: Deepwood Motte | E26: North | F26: 2 | G26: Hornwood, White Harbor, Torrhen's Square | H26: land | I26: 1-3 | J26: NO | K26: 3 | L26: 3 | M26: 2 | N26: 5 | O26: 2 | P26: NO | Q26: NO | R26: NO | S26: forest | T26: 1.5 | V26: house_glover | W26: Robett Glover | X26: old_gods | Y26: Deep Wolfswood fortress. | Z26: Wolfswood garrison | AA26: https://awoiaf.westeros.org/index.php/Deepwood_Motte
A27: PARTIAL | B27: Claude | C27: mormont_keep | D27: Mormont Keep | E27: North | F27: 2 | G27: White Harbor, Deepwood Motte | H27: land, sea | I27: 1-3 | J27: NO | K27: 3 | L27: 3 | M27: 2 | N27: 5 | O27: 2 | P27: YES | Q27: NO | R27: NO | S27: island | T27: 1.5 | V27: house_mormont | W27: Jeor Mormont | X27: old_gods | Y27: Island Northern fortress. | Z27: Island fortress | AA27: https://awoiaf.westeros.org/index.php/Mormont_Keep
A28: PARTIAL | B28: Claude | C28: greywater_watch | D28: Greywater Watch | E28: North | F28: 2 | G28: Moat Cailin, Winterfell | H28: land | I28: 1-3 | J28: NO | K28: 3 | L28: 3 | M28: 2 | N28: 5 | O28: 2 | P28: NO | Q28: NO | R28: NO | S28: swamp | T28: 1.5 | V28: house_reed | W28: Howland Reed | X28: old_gods | Y28: Mysterious swamp fortress. | Z28: Magical stronghold | AA28: https://awoiaf.westeros.org/index.php/Greywater_Watch
A29: PARTIAL | B29: Claude | C29: last_hearth | D29: Last Hearth | E29: North | F29: 2 | G29: Dreadfort, Karhold, Winterfell | H29: land | I29: 1-3 | J29: NO | K29: 3 | L29: 3 | M29: 2 | N29: 5 | O29: 2 | P29: NO | Q29: NO | R29: NO | S29: forest | T29: 1.5 | V29: house_umber | W29: Greatjon Umber | X29: old_gods | Y29: Northern fortress near Gift. | Z29: Wall proximity | AA29: https://awoiaf.westeros.org/index.php/Last_Hearth
A30: PARTIAL | B30: Claude | C30: torrhen_square | D30: Torrhen's Square | E30: North | F30: 2 | G30: Deepwood Motte, Castle Cerwyn, Hornwood | H30: land | I30: 1-3 | J30: NO | K30: 3 | L30: 3 | M30: 2 | N30: 5 | O30: 2 | P30: NO | Q30: NO | R30: NO | S30: plains | T30: 1.5 | V30: house_tallhart | W30: Leobald Tallhart | X30: old_gods | Y30: Northern plains fortress. | Z30: Named after ancient king | AA30: https://awoiaf.westeros.org/index.php/Torrhen_Square
A31: PARTIAL | B31: Claude | C31: wolfs_den | D31: Wolf's Den | E31: North | F31: 2 | G31: White Harbor, Deepwood Motte | H31: land, sea | I31: 1-3 | J31: NO | K31: 3 | L31: 3 | M31: 2 | N31: 5 | O31: 2 | P31: YES | Q31: NO | R31: NO | S31: coast | T31: 1.5 | V31: house_stark | W31: Unknown | X31: old_gods | Y31: Coastal Northern fortress. | Z31: Coastal defense | AA31: https://awoiaf.westeros.org/index.php/Wolfs_Den
A32: PARTIAL | B32: Claude | C32: oldcastle | D32: Oldcastle | E32: North | F32: 3 | G32: Last Hearth, Karhold | H32: land | I32: 1-3 | J32: NO | K32: 1 | L32: 1 | M32: 0 | N32: 3 | O32: 1 | P32: NO | Q32: NO | R32: NO | S32: mountains | T32: 2 | V32: house_locke | W32: Unknown | X32: old_gods | Y32: Far North mountain fortress. | Z32: Oldest fortress | AA32: https://awoiaf.westeros.org/index.php/Oldcastle
... A45: PARTIAL | B45: Claude | C45: kingshouse | D45: Kingshouse | E45: North | F45: 3 | G45: Last Hearth, Widows Watch | H45: land | I45: 1-3 | J45: NO | K45: 1 | L45: 1 | M45: 0 | N45: 3 | O45: 1 | P45: NO | Q45: NO | R45: NO | S45: tundra | T45: 2 | V45: unknown | W45: Unknown | X45: old_gods | Y45: Far North tundra fortress. | Z45: Wall access | AA45: https://awoiaf.westeros.org/index.php/Kingshouse
A46: PARTIAL | B46: Claude | C46: riverrun | D46: Riverrun | E46: Riverlands | F46: 1 | G46: The Twins, Harrenhal, Seagard | H46: land, sea | I46: 5 | J46: NO | K46: 5 | L46: 5 | M46: 4 | N46: 7 | O46: 3 | P46: NO | Q46: NO | R46: YES | S46: river | T46: 1 | U46: River fortress: naval advantage | V46: house_tully | W46: Hoster Tully | X46: faith_of_the_seven | Y46: Seat of House Tully, positioned at confluence of Red Fork and Tumblestone Rivers. Strong defensive position with riverine access. | Z46: Tully ancestral seat, War of Five Kings headquarters | AA46: https://awoiaf.westeros.org/index.php/Riverrun
A47: PARTIAL | B47: Claude | C47: harrenhal | D47: Harrenhal | E47: Riverlands | F47: 1 | G47: Riverrun, The Twins, Darry, Crakehall | H47: land | I47: 4 | J47: NO | K47: 5 | L47: 5 | M47: 4 | N47: 7 | O47: 3 | P47: NO | Q47: YES | R47: NO | S47: plains | T47: 1 | U47: Cursed castle: reduced morale | V47: unknown | W47: Unknown | X47: faith_of_the_seven | Y47: Massive ruined fortress in the Riverlands, built by House Hoare with dragon fire. Largest castle in the Seven Kingdoms by size but badly damaged. | Z47: Field of Fire Targaryen conquest, War of Five Kings strategic point | AA47: https://awoiaf.westeros.org/index.php/Harrenhal
A48: PARTIAL | B48: Claude | C48: the_twins | D48: The Twins | E48: Riverlands | F48: 1 | G48: Moat Cailin, Riverrun, The Trident | H48: land, sea | I48: 3 | J48: NO | K48: 5 | L48: 5 | M48: 4 | N48: 7 | O48: 3 | P48: YES | Q48: YES | R48: NO | S48: river | T48: 1 | U48: Bridge toll: +1 gold per crossing | V48: house_frey | W48: Walder Frey | X48: faith_of_the_seven | Y48: Seat of House Frey, twin castles on either side of the Trident River. Controls only major river crossing between North and South. | Z48: Frey ancestral seat, controls critical trade route | AA48: https://awoiaf.westeros.org/index.php/Twins
A49: PARTIAL | B49: Claude | C49: darry | D49: Darry | E49: Riverlands | F49: 2 | G49: Harrenhal, Riverrun, The Twins | H49: land | I49: 1-3 | J49: NO | K49: 3 | L49: 3 | M49: 2 | N49: 5 | O49: 2 | P49: NO | Q49: NO | R49: NO | S49: plains | T49: 1 | V49: house_darry | W49: Unknown | X49: faith_of_the_seven | Y49: Riverlands fortress. | Z49: Lannister occupation | AA49: https://awoiaf.westeros.org/index.php/Darry
A50: PARTIAL | B50: Claude | C50: raventree_hall | D50: Raventree Hall | E50: Riverlands | F50: 2 | G50: Riverrun, Stone Hedge, Harrenhal | H50: land | I50: 1-3 | J50: NO | K50: 3 | L50: 3 | M50: 2 | N50: 5 | O50: 2 | P50: NO | Q50: NO | R50: NO | S50: forest | T50: 1 | V50: house_blackwood | W50: Tytos Blackwood | X50: old_gods | Y50: Riverlands fortress with ancient tree. | Z50: Old Gods shrine | AA50: https://awoiaf.westeros.org/index.php/Raventree_Hall
A51: PARTIAL | B51: Claude | C51: stone_hedge | D51: Stone Hedge | E51: Riverlands | F51: 2 | G51: Raventree Hall, Riverrun, Harrenhal | H51: land | I51: 1-3 | J51: NO | K51: 3 | L51: 3 | M51: 2 | N51: 5 | O51: 2 | P51: NO | Q51: NO | R51: NO | S51: forest | T51: 1 | V51: house_bracken | W51: Humfrey Bracken | X51: faith_of_the_seven | Y51: Riverlands fortress. | Z51: Blackwood rival | AA51: https://awoiaf.westeros.org/index.php/Stone_Hedge
A52: PARTIAL | B52: Claude | C52: maidenpool | D52: Maidenpool | E52: Riverlands | F52: 2 | G52: Riverrun, Seagard, Harrenhal | H52: land, sea | I52: 1-3 | J52: NO | K52: 3 | L52: 3 | M52: 2 | N52: 5 | O52: 2 | P52: YES | Q52: NO | R52: NO | S52: coast | T52: 1 | V52: house_mooton | W52: Myles Mooton | X52: faith_of_the_seven | Y52: Riverlands port fortress. | Z52: Port city | AA52: https://awoiaf.westeros.org/index.php/Maidenpool
A53: PARTIAL | B53: Claude | C53: pinkmaiden_castle | D53: Pinkmaiden Castle | E53: Riverlands | F53: 2 | G53: Riverrun, Acorn Hall, Seagard | H53: land | I53: 1-3 | J53: NO | K53: 3 | L53: 3 | M53: 2 | N53: 5 | O53: 2 | P53: NO | Q53: NO | R53: NO | S53: river | T53: 1 | V53: house_piper | W53: Pia Piper | X53: faith_of_the_seven | Y53: Riverlands river fortress. | Z53: River fortress | AA53: https://awoiaf.westeros.org/index.php/Pinkmaiden_Castle
...

Sheet 📊 Progress
B2: DATA COLLECTION PROGRESS
B4: Region | C4: Total | D4: Complete | E4: Partial | F4: Stub
B5: Crownlands | C5: 16 | D5: =COUNTIFS('🏰 Castle Data'!$E$3:$E$1000,B5,'🏰 Castle Data'!$A$3:$A$1000,"COMPLETE") -> 0 | E5: =COUNTIFS('🏰 Castle Data'!$E$3:$E$1000,B5,'🏰 Castle Data'!$A$3:$A$1000,"PARTIAL") -> 16 | F5: =COUNTIFS('🏰 Castle Data'!$E$3:$E$1000,B5,'🏰 Castle Data'!$A$3:$A$1000,"STUB") -> 0
B6: North | C6: 27 | D6: =COUNTIFS('🏰 Castle Data'!$E$3:$E$1000,B6,'🏰 Castle Data'!$A$3:$A$1000,"COMPLETE") -> 0 | E6: =COUNTIFS('🏰 Castle Data'!$E$3:$E$1000,B6,'🏰 Castle Data'!$A$3:$A$1000,"PARTIAL") -> 27 | F6: =COUNTIFS('🏰 Castle Data'!$E$3:$E$1000,B6,'🏰 Castle Data'!$A$3:$A$1000,"STUB") -> 0
B7: Riverlands | C7: 24 | D7: =COUNTIFS('🏰 Castle Data'!$E$3:$E$1000,B7,'🏰 Castle Data'!$A$3:$A$1000,"COMPLETE") -> 0 | E7: =COUNTIFS('🏰 Castle Data'!$E$3:$E$1000,B7,'🏰 Castle Data'!$A$3:$A$1000,"PARTIAL") -> 24 | F7: =COUNTIFS('🏰 Castle Data'!$E$3:$E$1000,B7,'🏰 Castle Data'!$A$3:$A$1000,"STUB") -> 0
B8: Westerlands | C8: 17 | D8: =COUNTIFS('🏰 Castle Data'!$E$3:$E$1000,B8,'🏰 Castle Data'!$A$3:$A$1000,"COMPLETE") -> 0 | E8: =COUNTIFS('🏰 Castle Data'!$E$3:$E$1000,B8,'🏰 Castle Data'!$A$3:$A$1000,"PARTIAL") -> 17 | F8: =COUNTIFS('🏰 Castle Data'!$E$3:$E$1000,B8,'🏰 Castle Data'!$A$3:$A$1000,"STUB") -> 0
B9: Reach | C9: 33 | D9: =COUNTIFS('🏰 Castle Data'!$E$3:$E$1000,B9,'🏰 Castle Data'!$A$3:$A$1000,"COMPLETE") -> 0 | E9: =COUNTIFS('🏰 Castle Data'!$E$3:$E$1000,B9,'🏰 Castle Data'!$A$3:$A$1000,"PARTIAL") -> 33 | F9: =COUNTIFS('🏰 Castle Data'!$E$3:$E$1000,B9,'🏰 Castle Data'!$A$3:$A$1000,"STUB") -> 0
B10: Stormlands | C10: 18 | D10: =COUNTIFS('🏰 Castle Data'!$E$3:$E$1000,B10,'🏰 Castle Data'!$A$3:$A$1000,"COMPLETE") -> 0 | E10: =COUNTIFS('🏰 Castle Data'!$E$3:$E$1000,B10,'🏰 Castle Data'!$A$3:$A$1000,"PARTIAL") -> 18 | F10: =COUNTIFS('🏰 Castle Data'!$E$3:$E$1000,B10,'🏰 Castle Data'!$A$3:$A$1000,"STUB") -> 0
B11: Dorne | C11: 21 | D11: =COUNTIFS('🏰 Castle Data'!$E$3:$E$1000,B11,'🏰 Castle Data'!$A$3:$A$1000,"COMPLETE") -> 0 | E11: =COUNTIFS('🏰 Castle Data'!$E$3:$E$1000,B11,'🏰 Castle Data'!$A$3:$A$1000,"PARTIAL") -> 21 | F11: =COUNTIFS('🏰 Castle Data'!$E$3:$E$1000,B11,'🏰 Castle Data'!$A$3:$A$1000,"STUB") -> 0
B12: Vale | C12: 14 | D12: =COUNTIFS('🏰 Castle Data'!$E$3:$E$1000,B12,'🏰 Castle Data'!$A$3:$A$1000,"COMPLETE") -> 0 | E12: =COUNTIFS('🏰 Castle Data'!$E$3:$E$1000,B12,'🏰 Castle Data'!$A$3:$A$1000,"PARTIAL") -> 14 | F12: =COUNTIFS('🏰 Castle Data'!$E$3:$E$1000,B12,'🏰 Castle Data'!$A$3:$A$1000,"STUB") -> 0
B13: Iron Islands | C13: 18 | D13: =COUNTIFS('🏰 Castle Data'!$E$3:$E$1000,B13,'🏰 Castle Data'!$A$3:$A$1000,"COMPLETE") -> 0 | E13: =COUNTIFS('🏰 Castle Data'!$E$3:$E$1000,B13,'🏰 Castle Data'!$A$3:$A$1000,"PARTIAL") -> 18 | F13: =COUNTIFS('🏰 Castle Data'!$E$3:$E$1000,B13,'🏰 Castle Data'!$A$3:$A$1000,"STUB") -> 0
B14: TOTAL | C14: =SUM(C5:C13) -> 188 | D14: =SUM(D5:D13) -> 0 | E14: =SUM(E5:E13) -> 188 | F14: =SUM(F5:F13) -> 0

Sheet 📋 House Instructions
B2: WESTEROS HOUSES DATA COLLECTION
B3: Collect data on every Great House and notable Noble House across Westeros
B6: YOUR JOB
B7: Step 1 | C7: Go to the 🏠 House Data sheet
B8: Step 2 | C8: Find a row with Status = STUB (highlighted red)
B9: Step 3 | C9: Visit the wiki URL in the last column for that house
B10: Step 4 | C10: Fill in as many columns as you can from the wiki infobox and page content
B11: Step 5 | C11: Change Status to PARTIAL when started, COMPLETE when done
B12: Step 6 | C12: Move to the next STUB row and repeat
B14: WHAT THE WIKI GIVES YOU
B15: Infobox | C15: Coat of arms description, Seat (castle), Head of house, Region, Titles, Overlords, Words/Motto, Ancestral weapons
B16: Page body | C16: History summary, notable members, current status, alliances
B17: Member list | C17: Named members with roles -- collect the head and heir at minimum
B19: COLUMN GUIDE
B20: status | C20: STUB / PARTIAL / COMPLETE
B21: slug | C21: Auto-filled. Don't edit.
B22: name | C22: Auto-filled. Don't edit.
B23: region | C23: Auto-filled. Don't edit.
B24: house_rank | C24: Auto-filled. Don't edit. (great / noble / minor / knightly)
B25: current_status | C25: Auto-filled as active. Change if extinct/exiled/deposed at start of AGOT
B26: seat_castle | C26: The castle they rule -- must match a slug from the Castle Data sheet (e.g. mormont_keep)
B27: sigil_description | C27: Text description of their coat of arms from wiki. e.g. 'A black bear over a green wood'
B28: house_words | C28: Their motto/words. e.g. 'Here We Stand'. Leave blank if unknown.
B29: overlord_house | C29: Which Great House they are sworn to. e.g. house_stark
B30: head_of_house | C30: Name of the lord/lady at the start of AGOT. e.g. Lady Maege Mormont
B31: head_title | C31: Their title. e.g. Lady of Bear Island, Lord of Casterly Rock
... B42: notable_history | C42: 1-2 key historical events worth knowing for game flavor
B44: HOUSE RANK GUIDE
B45: great | C45: The 9 paramount houses: Stark, Lannister, Tyrell, Baratheon, Arryn, Tully, Greyjoy, Martell, Targaryen (exiled)
B46: noble | C46: Lords with their own castles and sworn banners. The bulk of houses.
B47: minor | C47: Landed knights and small holdings. Fewer named members.
B48: knightly | C48: Knight houses with no castle of their own. Lowest tier.
B50: PRIORITY ORDER
B51: Priority 1 | C51: All Great Houses -- fill these completely first
B52: Priority 2 | C52: All houses that control Tier 1 or Tier 2 castles
B53: Priority 3 | C53: Remaining noble houses with castles in the database
B54: Priority 4 | C54: Minor and knightly houses -- basic info only
B56: TIPS
B57: Overlords | C57: The infobox always shows the overlord house. Use the house slug format (lowercase, underscore).
B58: Wealth clues | C58: Pages mention poverty ('poor house'), richness ('wealthiest'), mines, trade routes
...

Sheet 🏠 House Data
A1: META | C1: IDENTITY | H1: HERALDRY | J1: SEAT | K1: HIERARCHY | O1: MEMBERS | S1: GAME STATS | W1: LORE
A2: status | B2: collected_by | C2: slug | D2: name | E2: region | F2: house_rank | G2: current_status | H2: sigil_description | I2: house_words | J2: seat_castle | K2: overlord_house | L2: head_of_house | M2: head_title | N2: heir | O2: ancestral_weapon | P2: notable_members | Q2: allies_at_game_start | R2: enemies_at_game_start | S2: wealth_rating | T2: military_rating | U2: influence_rating | V2: unique_trait | W2: short_description | X2: notable_history | Y2: wiki_url
A3: PARTIAL | B3: Claude | C3: house_stark | D3: House Stark | E3: North | F3: great | G3: A grey direwolf on a white field | H3: Winter is Coming | I3: winterfell | K3: Ned Stark | L3: Warden of the North / King in the North | M3: Robb Stark | N3: Ice (Valyrian steel greatsword) | O3: Catelyn Stark, Arya Stark, Sansa Stark, Jon Snow, Bran Stark, Rickon Stark | P3: house_arryn, house_tully, house_baratheon | Q3: house_lannister, house_bolton | R3: house_bolton | S3: 8 | T3: 9 | U3: Warden bonuses: +1 to all Northern castles. Harsh winter resilience. | V3: Ancient house of the North, ruling from Winterfell for thousands of years. Follow the Old Gods and descend from the First Men. Known for honor, loyalty, and direwolf sigil. | W3: Brandon the Builder founded the house. Repelled the Andal invasion at Moat Cailin. Robert's Rebellion against the Targaryens. | Y3: https://awoiaf.westeros.org/index.php/House_Stark
A4: PARTIAL | B4: Claude | C4: house_lannister | D4: House Lannister | E4: Westerlands | F4: great | G4: A golden lion on a crimson field | H4: Hear Me Roar | I4: casterly_rock | K4: Tywin Lannister | L4: Warden of the West | M4: Cersei Lannister | N4: None known (house wealth instead) | O4: Cersei Lannister, Tyrion Lannister, Jaime Lannister, Kevan Lannister | P4: house_frey, house_baratheon | Q4: house_stark, house_tully | R4: house_stark, house_riverlands | S4: 10 | T4: 9 | U4: Golden Tooth: +2 gold per turn. Wealth advantage. | V4: Wealthiest great house of the Seven Kingdoms, controlling vast gold mines in the Westerlands. Known for cunning, ambition, and ruthlessness. | W4: Lannister ancestral line goes back thousands of years. Fought Targaryens in Field of Fire. Dominant power in recent decades. | Y4: https://awoiaf.westeros.org/index.php/House_Lannister
A5: PARTIAL | B5: Claude | C5: house_tyrell | D5: House Tyrell | E5: Reach | F5: great | G5: A green rose on a green field | H5: Growing Strong | I5: highgarden | K5: Mace Tyrell | L5: Warden of the South / Lord of the Reach | M5: Willas Tyrell | N5: None known (fertility and culture) | O5: Cersei Lannister (married), Margaery Tyrell, Loras Tyrell, Randyll Tarly | P5: house_baratheon, house_hightower | Q5: house_martell, house_stormlands | R5: house_dorne, house_stormlands | S5: 9 | T5: 7 | U5: Highgarden bonus: +1 gold all Reach castles. Most fertile region. | V5: Powerful great house of the Reach controlling the most fertile lands in the Seven Kingdoms. Known for prosperity, flowers, and shrewd politics. | W5: Relatively young house compared to others. Flourished under Targaryen rule. Became dominant power of the Reach. | Y5: https://awoiaf.westeros.org/index.php/House_Tyrell
A6: PARTIAL | B6: Claude | C6: house_baratheon | D6: House Baratheon | E6: Stormlands | F6: great | G6: A gold stag on a black field | H6: Ours is the Fury | I6: storms_end | K6: Robert Baratheon | L6: King of the Seven Kingdoms | M6: Joffrey Baratheon | N6: Warhammer (Robert's favorite) | O6: Cersei Lannister, Joffrey Baratheon, Myrcella Baratheon, Tommen Baratheon, Stannis Baratheon, Renly Baratheon | P6: house_lannister, house_tyrell | Q6: house_stark, house_greyjoy | R6: house_dorne, house_reach | S6: 7 | T6: 9 | U6: Iron Throne control: bonuses to King's Landing | V6: Great house of the Stormlands, founded during Aegon's Conquest. Robert Baratheon sits the Iron Throne after rebellion against the Targaryens. | W6: Robert's Rebellion overthrew the Targaryen dynasty. Two branches: original (Storm's End) and newer (King's Landing). | Y6: https://awoiaf.westeros.org/index.php/House_Baratheon
A7: PARTIAL | B7: Claude | C7: house_arryn | D7: House Arryn | E7: Vale | F7: great | G7: A white falcon and crescent moon on a blue field | H7: As High as Honor | I7: the_eyrie | K7: Jon Arryn | L7: Warden of the East / Lord of the Eyrie | M7: Robert Arryn | N7: None known | O7: Catelyn Stark (married), Lysa Arryn, Sansa Stark (betrothed) | P7: house_stark, house_tully, house_baratheon | Q7: house_greyjoy | R7: house_north | S7: 7 | T7: 7 | U7: Eyrie immunity: Cannot be besieged in summer. Mountain protection. | V7: Ancient house of the Vale of Arryn, ruling from the impregnable Eyrie. Known for honor, nobility, and mountain strength. | W7: One of the oldest houses. Jon Arryn served as Hand to Robert Baratheon. Andal-descended house. | Y7: https://awoiaf.westeros.org/index.php/House_Arryn
A8: PARTIAL | B8: Claude | C8: house_tully | D8: House Tully | E8: Riverlands | F8: great | G8: A silver trout on a red and blue field | H8: Family, Duty, Honor | I8: riverrun | K8: Hoster Tully | L8: Lord of the Riverlands / Warden of the Riverlands | M8: Edmure Tully | N8: None known | O8: Catelyn Stark (married), Lysa Arryn (married), Edmure Tully | P8: house_stark, house_arryn, house_baratheon | Q8: house_lannister, house_greyjoy | R8: house_lannister, house_greyjoy | S8: 6 | T8: 7 | U8: River commerce: +1 gold for water-connected castles | V8: Great house of the Riverlands controlling the rivers and crossroads. Known for family loyalty and river control from Riverrun. | W8: Relatively new great house. Key position between North, Vale, and Westerlands. Alliance-builders through marriages. | Y8: https://awoiaf.westeros.org/index.php/House_Tully
A9: PARTIAL | B9: Claude | C9: house_greyjoy | D9: House Greyjoy | E9: Iron Islands | F9: great | G9: A golden kraken on a black field | H9: We Do Not Sow | I9: pyke | K9: Balon Greyjoy | L9: King of the Iron Islands | M9: Theon Greyjoy | N9: None known (Valyrian steel swords rare) | O9: Theon Greyjoy, Asha Greyjoy, Rodrik Harlaw | P9: house_bolton, house_frey | Q9: house_stark, house_tully, house_baratheon | R9: house_north, house_riverlands | S9: 4 | T9: 8 | U9: Naval dominance: Iron Fleet strength. Cannot use land routes. | V9: Powerful house of the Iron Islands following the Drowned God. Warlike seafaring culture, raiding tradition, and naval strength. | W9: Ancient house from the Iron Age of the First Men. Targaryen rebellion. Defiant culture resistant to conquest. | Y9: https://awoiaf.westeros.org/index.php/House_Greyjoy
A10: PARTIAL | B10: Claude | C10: house_martell | D10: House Martell | E10: Dorne | F10: great | G10: A red sun pierced by a gold spear on an orange field | H10: Unbowed, Unbent, Unbroken | I10: sunspear | K10: Doran Martell | L10: Prince of Dorne | M10: Trystane Martell | N10: None known | O10: Doran Martell, Oberyn Martell, Elia Martell, Arianne Martell | P10: house_tyrell | Q10: house_baratheon, house_lannister | R10: house_reach, house_stormlands | S10: 7 | T10: 7 | U10: Desert terrain: Non-Dorne armies suffer attrition. Only 2 entry points. | V10: Powerful house of Dorne, never fully conquered by Targaryens. Known for independence, scheming, and desert warfare tactics. | W10: Never submitted to Targaryen dragons. Maintains peace and prosperity in Dorne. Known for intricate political schemes. | Y10: https://awoiaf.westeros.org/index.php/House_Martell
A11: PARTIAL | B11: Claude | C11: house_targaryen | D11: House Targaryen | E11: Crownlands | F11: great | G11: A three-headed red dragon on a black field | H11: Fire and Blood | I11: dragonstone | K11: Daenerys Targaryen | L11: Queen of the Dragons / Dragon's Daughter | M11: None | N11: None (dragons) | O11: Rhaegar Targaryen, Rhealla Targaryen, Viserys Targaryen | P11: none | Q11: all | R11: none | S11: 6 | T11: 5 | U11: Dragons: Ultimate power. Daenerys not yet known in Westeros. | V11: Ancient house of dragon lords from Valyria who conquered Westeros 300 years ago. Dynasty recently ended by Robert's Rebellion. | W11: Conquered Westeros with dragons. Ruled for 300 years. Mad King's regime and Mad King Aerys II death sparked Robert's Rebellion. | Y11: https://awoiaf.westeros.org/index.php/House_Targaryen
A12: PARTIAL | B12: Claude | C12: house_hightower | D12: House Hightower | E12: Reach | F12: noble | G12: A white tower on a grey field | H12: We Light the Way | I12: hightower | K12: Unknown | L12: Lord of Hightower / Steward of the Citadel | M12: Unknown | N12: None known | O12: Unknown | P12: house_tyrell | Q12: none | R12: house_dorne, house_stormlands | S12: 8 | T12: 6 | U12: Citadel knowledge: +1 to intel | V12: Powerful Reach house with ancient roots. Seat is the legendary Hightower. Stewards of the Citadel and Maesters. | W12: One of oldest houses. Hightower built by First Men. Stewards of knowledge. | Y12: https://awoiaf.westeros.org/index.php/House_Hightower
A13: PARTIAL | B13: Claude | C13: house_bolton | D13: House Bolton | E13: North | F13: noble | G13: A flayed man on a pink field | H13: Our Blades Are Sharp | I13: the_dreadfort | K13: Roose Bolton | L13: Warden of the North (contested) | M13: Ramsay Bolton | N13: None known | O13: Ramsay Bolton, Walda Frey | P13: house_frey, house_lannister | Q13: house_stark | R13: house_bolton | S13: 4 | T13: 7 | U13: Dread Flaying: +1 intimidation. Disloyal vassal mechanic. | V13: Powerful Northern house known for cruelty and flaying. Ancient rivals to House Stark. Seat is the grim Dreadfort. | W13: Brandon the Breaker attempted to conquer the North. Joined Lannisters against Starks in War of Five Kings. | Y13: https://awoiaf.westeros.org/index.php/House_Bolton
A14: PARTIAL | B14: Claude | C14: house_mormont | D14: House Mormont | E14: North | F14: noble | G14: A black bear on a green field | H14: Here We Stand | I14: bear_island | K14: Jeor Mormont | L14: Lord Commander of the Night's Watch (former) | M14: Dacey Mormont | N14: Longclaw (Valyrian steel, in custody of Jon Snow) | O14: Jeor Mormont, Jorah Mormont, Lyanna Mormont | P14: house_stark, house_manderly | Q14: none | R14: house_bolton | S14: 2 | T14: 4 | U14: Bear Island strength: +1 to naval forces | V14: Northern house from Bear Island, loyal to the Starks. Known for producing strong warriors and sailors. | W14: Jeor Mormont leads Night's Watch. Jorah Mormont pledged to Daenerys. | Y14: https://awoiaf.westeros.org/index.php/House_Mormont
... A121: PARTIAL | B121: Claude | C121: house_sunglass | D121: House Sunglass | E121: Crownlands | F121: noble | G121: A gold sun on a red field | H121: None known | I121: sweetport_sound | K121: Unknown | L121: Lord of Sweetport Sound | M121: Unknown | N121: None known | O121: Unknown | P121: house_baratheon_kings_landing | Q121: none | R121: none | S121: 3 | T121: 3 | U121: Port access: trade bonus | V121: Crownlands house. Coastal positions. Maritime traditions. | W121: House with port holdings in Crownlands. | Y121: https://awoiaf.westeros.org/index.php/House_Sunglass

Sheet 📊 House Progress
B2: HOUSE DATA COLLECTION PROGRESS
B4: Region | C4: Total | D4: Complete | E4: Partial | F4: Stub
B5: North | C5: 17 | D5: =COUNTIFS('🏠 House Data'!$E$3:$E$1000,B5,'🏠 House Data'!$A$3:$A$1000,"COMPLETE") -> 0 | E5: =COUNTIFS('🏠 House Data'!$E$3:$E$1000,B5,'🏠 House Data'!$A$3:$A$1000,"PARTIAL") -> 17 | F5: =COUNTIFS('🏠 House Data'!$E$3:$E$1000,B5,'🏠 House Data'!$A$3:$A$1000,"STUB") -> 0
B6: Riverlands | C6: 14 | D6: =COUNTIFS('🏠 House Data'!$E$3:$E$1000,B6,'🏠 House Data'!$A$3:$A$1000,"COMPLETE") -> 0 | E6: =COUNTIFS('🏠 House Data'!$E$3:$E$1000,B6,'🏠 House Data'!$A$3:$A$1000,"PARTIAL") -> 14 | F6: =COUNTIFS('🏠 House Data'!$E$3:$E$1000,B6,'🏠 House Data'!$A$3:$A$1000,"STUB") -> 0
B7: Westerlands | C7: 13 | D7: =COUNTIFS('🏠 House Data'!$E$3:$E$1000,B7,'🏠 House Data'!$A$3:$A$1000,"COMPLETE") -> 0 | E7: =COUNTIFS('🏠 House Data'!$E$3:$E$1000,B7,'🏠 House Data'!$A$3:$A$1000,"PARTIAL") -> 13 | F7: =COUNTIFS('🏠 House Data'!$E$3:$E$1000,B7,'🏠 House Data'!$A$3:$A$1000,"STUB") -> 0
B8: Reach | C8: 15 | D8: =COUNTIFS('🏠 House Data'!$E$3:$E$1000,B8,'🏠 House Data'!$A$3:$A$1000,"COMPLETE") -> 0 | E8: =COUNTIFS('🏠 House Data'!$E$3:$E$1000,B8,'🏠 House Data'!$A$3:$A$1000,"PARTIAL") -> 15 | F8: =COUNTIFS('🏠 House Data'!$E$3:$E$1000,B8,'🏠 House Data'!$A$3:$A$1000,"STUB") -> 0
B9: Stormlands | C9: 12 | D9: =COUNTIFS('🏠 House Data'!$E$3:$E$1000,B9,'🏠 House Data'!$A$3:$A$1000,"COMPLETE") -> 0 | E9: =COUNTIFS('🏠 House Data'!$E$3:$E$1000,B9,'🏠 House Data'!$A$3:$A$1000,"PARTIAL") -> 12 | F9: =COUNTIFS('🏠 House Data'!$E$3:$E$1000,B9,'🏠 House Data'!$A$3:$A$1000,"STUB") -> 0
B10: Dorne | C10: 14 | D10: =COUNTIFS('🏠 House Data'!$E$3:$E$1000,B10,'🏠 House Data'!$A$3:$A$1000,"COMPLETE") -> 0 | E10: =COUNTIFS('🏠 House Data'!$E$3:$E$1000,B10,'🏠 House Data'!$A$3:$A$1000,"PARTIAL") -> 14 | F10: =COUNTIFS('🏠 House Data'!$E$3:$E$1000,B10,'🏠 House Data'!$A$3:$A$1000,"STUB") -> 0
B11: Vale | C11: 11 | D11: =COUNTIFS('🏠 House Data'!$E$3:$E$1000,B11,'🏠 House Data'!$A$3:$A$1000,"COMPLETE") -> 0 | E11: =COUNTIFS('🏠 House Data'!$E$3:$E$1000,B11,'🏠 House Data'!$A$3:$A$1000,"PARTIAL") -> 11 | F11: =COUNTIFS('🏠 House Data'!$E$3:$E$1000,B11,'🏠 House Data'!$A$3:$A$1000,"STUB") -> 0
B12: Iron Islands | C12: 11 | D12: =COUNTIFS('🏠 House Data'!$E$3:$E$1000,B12,'🏠 House Data'!$A$3:$A$1000,"COMPLETE") -> 0 | E12: =COUNTIFS('🏠 House Data'!$E$3:$E$1000,B12,'🏠 House Data'!$A$3:$A$1000,"PARTIAL") -> 11 | F12: =COUNTIFS('🏠 House Data'!$E$3:$E$1000,B12,'🏠 House Data'!$A$3:$A$1000,"STUB") -> 0
B13: Crownlands | C13: 12 | D13: =COUNTIFS('🏠 House Data'!$E$3:$E$1000,B13,'🏠 House Data'!$A$3:$A$1000,"COMPLETE") -> 0 | E13: =COUNTIFS('🏠 House Data'!$E$3:$E$1000,B13,'🏠 House Data'!$A$3:$A$1000,"PARTIAL") -> 12 | F13: =COUNTIFS('🏠 House Data'!$E$3:$E$1000,B13,'🏠 House Data'!$A$3:$A$1000,"STUB") -> 0
B14: TOTAL | C14: =SUM(C5:C13) -> 119 | D14: =SUM(D5:D13) -> 0 | E14: =SUM(E5:E13) -> 119 | F14: =SUM(F5:F13) -> 0

Sheet 📋 Region Instructions
B2: WESTEROS REGIONS DATA COLLECTION
B3: 9 rows -- one per region. Each region page has Geography / Seasons / People / Economy / Military / History / Houses sections.
B6: WHAT TO DO
B7: Step 1 | C7: Go to the 🗺️ Region Data sheet
B8: Step 2 | C8: Click the wiki_url link for the region (last column)
B9: Step 3 | C9: Work through each section of the wiki page filling in the columns below
B10: Step 4 | C10: Mark status COMPLETE when all key fields are filled
B12: WIKI PAGE STRUCTURE
B13: Geography section | C13: Fill: terrain types, major rivers, major roads, coastline status, geographic barriers, island names (if any)
B14: Seasons section | C14: Fill: climate_baseline, winter_severity_notes. Note any unique seasonal mechanics.
B15: People section | C15: Fill: cultural_identity, subcultures, religion, bastard_surname, unique_customs
B16: Economy section | C16: Fill: key_resources, trade_goods, major_ports, economic_notes
B17: Military strength section | C17: Fill: military_size_estimate, military_notes, cavalry_vs_infantry, fleet_strength
B18: History section | C18: Fill: historical_enemies, notable_history. Look for ancient rivalries and wars.
B19: Houses section | C19: Fill: great_house, notable_bannermen (top 5-6 most important). List is at bottom of page.
B21: COLUMN GUIDE
B22: status | C22: STUB / PARTIAL / COMPLETE
B23: region_name | C23: Auto-filled.
B24: great_house | C24: The ruling Great House. e.g. house_stark
B25: ancient_title | C25: King title before Aegon's Conquest. Usually in intro paragraph.
B26: victory_title | C26: What the winning player is called. Derived from ancient_title.
B27: cultural_identity | C27: From People section. e.g. Northmen, Ironborn, Dornishmen, Reachmen
B28: subcultures | C28: Notable sub-groups. e.g. Crannogmen, Mountain Clans, Skagosi for North. Comma-separated.
B29: bastard_surname | C29: Regional bastard surname. e.g. Snow (North), Sand (Dorne), Storm (Stormlands), Flowers (Reach), Rivers (Riverlands), Stone (Vale), Hill (Westerlands), Pyke (Iron Islands), Waters (Crownlands)
B30: primary_religion | C30: Dominant religion. Options: faith_of_the_seven / old_gods / drowned_god / rhlor / unknown
B31: secondary_religion | C31: Any significant secondary faith. Often faith_of_the_seven where old_gods is primary.
B32: dominant_terrain | C32: Main terrain type: plains / forest / mountains / coast / island / river / swamp / desert / tundra
B33: secondary_terrain | C33: Second terrain type if notable
... B56: wiki_url | C56: Auto-filled. Click to visit.
B58: PRIORITY NOTES
B59: Most important columns | C59: cultural_identity, primary_religion, dominant_terrain, major_rivers, major_roads, chokepoints, key_resources, military_size_estimate, fleet_strength, historical_enemies, regional_special_rule
B60: Can skip for now | C60: winter_severity_notes, trade_goods, cavalry_vs_infantry (fill later for flavor text)
B61: North is already done | C61: Use the North row as a reference for how detailed other regions should be
B63: BASTARD SURNAMES (all regions)
B64: North | C64: Snow
B65: Riverlands | C65: Rivers
B66: Westerlands | C66: Hill
B67: Reach | C67: Flowers
B68: Stormlands | C68: Storm
B69: Dorne | C69: Sand
...

Sheet 🗺️ Region Data
A1: IDENTITY | E1: CULTURE | J1: RELIGION | L1: TERRAIN | U1: ECONOMY | Y1: MILITARY | AC1: GAME RULES | AH1: LORE
A2: status | B2: collected_by | C2: region_name | D2: great_house | E2: ancient_title | F2: victory_title | G2: cultural_identity | H2: subcultures | I2: bastard_surname | J2: primary_religion | K2: secondary_religion | L2: dominant_terrain | M2: secondary_terrain | N2: climate_baseline | O2: winter_severity_notes | P2: has_coastline | Q2: major_rivers | R2: major_roads | S2: geographic_barriers | T2: island_names | U2: key_resources | V2: trade_goods | W2: major_ports | X2: economic_notes | Y2: military_size_estimate | Z2: cavalry_vs_infantry | AA2: fleet_strength | AB2: military_notes | AC2: chokepoints | AD2: regional_special_rule | AE2: sellsword_culture | AF2: historical_enemies | AG2: notable_bannermen | AH2: short_description | AI2: notable_history | AJ2: wiki_url
A3: PARTIAL | C3: North | D3: house_stark | E3: King in the North / King of Winter | F3: King in the North | G3: Northmen | H3: Crannogmen (House Reed), Mountain Clans (Flint, Norrey, Liddle, Wull, Harclay), Skagosi, Wolfswood Clans | I3: Snow | J3: old_gods | K3: faith_of_the_seven | L3: forest | M3: tundra | N3: 1.5 | O3: Snows can fall 40 feet deep. Widespread famine common. Lords store 1/5 to 1/4 of grain before autumn. Many die each winter. | P3: YES | Q3: White Knife, Fever River, Last River, Weeping Water, Green Fork (source in Neck) | R3: King's Road (Castle Black to Riverlands) | S3: The Wall (north), The Neck/Moat Cailin (south), Shivering Sea (east), Sunset Sea (west) | T3: Bear Island, Skagos, Skane | U3: Timber, wool, hides, fish | V3: Wool, hides, timber, fish, furs | W3: White Harbor | X3: Largely uncultivated, few roads. Most trade via King's Road or rivers. White Harbor has silversmiths and Old Mint. | Y3: ~45,000 maximum; ~20,000 on short notice near autumn | Z3: 4:1 infantry to cavalry. Manderly commands most heavy horse. | AA3: none | AB3: No naval strength since Brandon the Burner destroyed the fleet. Few knights (Old Gods faith). Mail most common armor. Very few cavalry. | AC3: Moat Cailin (only southern land entry), Wolf's Den / White Harbor (eastern coast) | AD3: Armies entering from south must pass Moat Cailin. Controlling it halves enemy march speed into the North. Eyrie-equivalent isolation: The Neck is swamp terrain -- armies crossing without Moat Cailin suffer attrition. | AE3: NO | AF3: Iron Islands, Vale of Arryn (War Across the Water) | AG3: house_bolton, house_umber, house_manderly, house_karstark, house_mormont, house_glover | AH3: The largest region of the Seven Kingdoms, ruled by House Stark from Winterfell for thousands of years. Sparsely populated with harsh winters, vast wilderness, and people descended from the First Men who follow the Old Gods. | AI3: Only kingdom to repel the Andal invasion (held at Moat Cailin). Brandon the Burner destroyed the northern fleet in grief, leaving North without sea power permanently. | AJ3: https://awoiaf.westeros.org/index.php/North
A4: PARTIAL | B4: Claude | C4: Riverlands | D4: house_tully | E4: King of the Trident | F4: Rivermen | G4: River lords (Tully, Blackwood, Bracken, Mallister), Crannogmen influences from Neck | H4: Rivers | I4: faith_of_the_seven | J4: old_gods | K4: river | L4: plains | M4: 1.0 | N4: Moderate winters. Fertile farmland generally survives harsh seasons. | O4: YES | P4: Red Fork, Blue Fork, Green Fork, Tumblestone River, Trident | Q4: King's Road, River Road | R4: The Neck (north), rivers form natural barriers throughout region | S4: Isle of Swans, scattered islands in the rivers | T4: Fertile farmland, fish, river trade, grain | U4: Grain, fish, lumber, agricultural products | V4: Seagard, Maidenpool | W4: Most valuable farmland in the Seven Kingdoms. River trade crucial. Harrenhal controls central Riverlands. | X4: ~30,000 maximum; ~15,000 on short notice | Y4: 3:2 mix, decent cavalry from open plains | Z4: weak | AA4: Good mix of heavy and light forces. River lords have distinct traditions. Vulnerable to invasion from north and east. | AB4: The Twins (only river crossing north-south), Harrenhal (central Riverlands control) | AC4: The Twins controls all major river crossings. Any army without a boat must pay a toll (gold cost) or capture The Twins to cross freely. Harrenhal captures lock down Riverlands. | AD4: River knights and lesser lords willing to sell service; mercenary bands active | AE4: Iron Islands (raiding), Westerlands (border conflicts) | AF4: house_frey, house_blackwood, house_bracken, house_mallister, house_darry, house_vance | AG4: house_frey, house_blackwood, house_bracken, house_mallister, house_darry | AJ4: https://awoiaf.westeros.org/index.php/Riverlands
A5: PARTIAL | B5: Claude | C5: Westerlands | D5: house_lannister | E5: King of the Rock | F5: Westermen | G5: Mountain clans (Crakehall, Marbrand, Westerling, Banefort, Prester), valley lords | H5: Hill | I5: faith_of_the_seven | J5: unknown | K5: mountains | L5: forest | M5: 1.0 | N5: Mountain winters are harsh but manageable. Protected by natural barriers. | O5: YES | P5: Tumblestone River (shared with Riverlands) | Q5: Gold Road (east-west trade route) | R5: Mountains on all sides, Golden Tooth pass controls eastern entry | S5: None | T5: Gold, silver, gems, metals—wealthiest region | U5: Gold, silver, metalwork, wine | V5: Lannisport, Kayce | W5: Gold mines generate enormous wealth. Golden Tooth pass controls trade. Most economically powerful region. | X5: ~35,000 maximum; ~20,000 readily available | Y5: 2:3 infantry-heavy, fewer cavalry in mountains | Z5: moderate | AA5: Mountain strongholds make defense strong. Limited cavalry in terrain. Naval presence via Lannisport. | AB5: Golden Tooth (eastern mountain pass), Casterly Rock (coastal fortress) | AC5: Gold mines generate +2 bonus gold per production cycle for the controlling house. Golden Tooth pass: attackers suffer -2 combat rolls. | AD5: Mountain mercenaries and sell-swords for hire; less organized than other regions | AE5: Riverlands (border conflicts), North (ancient rivalries) | AF5: house_crakehall, house_marbrand, house_westerling, house_banefort, house_prester, house_lefford | AG5: house_crakehall, house_marbrand, house_westerling, house_banefort, house_prester | AJ5: https://awoiaf.westeros.org/index.php/Westerlands
A6: PARTIAL | B6: Claude | C6: Reach | D6: house_tyrell | E6: King of the Reach | F6: Reachmen | G6: Hightower (Oldtown), Redwyne (Shield Islands), Tarly (Marches), Oakheart, Florent | H6: Flowers | I6: faith_of_the_seven | J6: unknown | K6: plains | L6: forest | M6: 1.0 | N6: Mild winters. Most fertile region—abundance and prosperity year-round. | O6: YES | P6: Mander River, Honeywine River, Blueburn River | Q6: Rose Road, Roseroad (main trade route) | R6: None significant—open and accessible | S6: Shield Islands (offshore) | T6: Grain, wine, horses, fish—most fertile and populous region | U6: Grain, wine, horses, food, luxury items | V6: Oldtown, Highgarden (river access), Three Towers | W6: Most fertile lands. Highgarden generates wealth. Oldtown is major cultural and trade center. | X6: ~40,000 maximum; ~25,000 readily available | Y6: 2:3 mix, excellent cavalry from plains | Z6: strong | AA6: House Redwyne commands large fleet from Shield Islands. Most populous region. Strong composite forces. | AB6: Highgarden (regional control), Hightower (Oldtown) | AC6: Holding Highgarden gives +1 gold to all Reach castles you control. Most fertile region: +1 base gold to all Reach castles during summer ticks. | AD6: Wealthy merchants hire sell-swords; organized mercenary bands | AE6: Dorne (border conflicts), Stormlands (historical rivalries) | AF6: house_redwyne, house_hightower, house_tarly, house_florent, house_oakheart, house_rowan | AG6: house_redwyne, house_hightower, house_tarly, house_florent, house_oakheart | AJ6: https://awoiaf.westeros.org/index.php/Reach
A7: PARTIAL | B7: Claude | C7: Stormlands | D7: house_baratheon | E7: Storm King | F7: Stormlanders | G7: Dornish Marches (Swann, Tarth, Dondarrion, Selmy, Caron) | H7: Storm | I7: faith_of_the_seven | J7: unknown | K7: forest | L7: coast | M7: 1.0 | N7: Storms frequent and severe. Unpredictable weather hazards. | O7: YES | P7: Wendwater River, Slayne River | Q7: King's Road (main north-south route) | R7: Cape Wrath (dangerous coast), Dornish Marches (open to Dorne) | S7: None significant | T7: Timber, fish, horses | U7: Timber, fish, horses, leather | V7: Storm's End (coastal), Cape Wrath | W7: Moderately wealthy. Trade via King's Road and coastal access. | X7: ~25,000 maximum; ~12,000 readily available | Y7: 2:3 infantry-heavy, good light cavalry | Z7: weak | AA7: Known for fierce fighters. Storm's End nearly impregnable. Limited naval strength. | AB7: Storm's End (only major castle), Blackhaven (Dornish Marches) | AC7: Storm's End: defending army gets +3 defense bonus—highest in the game. Random storm events delay fleet movement 1 in 5 ticks. | AD7: Marcher lords hire mercenaries; active sell-sword bands | AE7: Dorne (Marches conflicts), Reach (historical rivalries) | AF7: house_swann, house_tarth, house_dondarrion, house_selmy, house_caron, house_estermont | AG7: house_swann, house_tarth, house_dondarrion, house_selmy, house_caron | AJ7: https://awoiaf.westeros.org/index.php/Stormlands
A8: PARTIAL | B8: Claude | C8: Dorne | D8: house_martell | E8: Prince of Dorne / King of Dorne | F8: Dornishmen | G8: Orphans of the Greenblood (Rhoynar river people), desert lords, mountain clans | H8: Sand | I8: faith_of_the_seven | J8: unknown | K8: desert | L8: mountains | M8: 0.5 | N8: Mild winters. Desert terrain means other hazards—attrition from heat for non-Dornish armies. | O8: YES | P8: Greenblood River | Q8: Princes Pass, Boneway (only 2 land entry routes) | R8: Red Mountains (only 2 passes: Princes Pass and Boneway) | S8: None | T8: Spices, exotic goods, water rights, olives, salt | U8: Spices, exotic items, wine, olives, salt | V8: Sunspear, Planky Town | W8: Wealth from trade with Essos and mysterious goods. Independent economy. | X8: ~20,000 maximum; ~10,000 readily available | Y8: 3:2 cavalry-heavy, light cavalry and guerrilla tactics | Z8: moderate | AA8: Dornish rely on guerrilla tactics and terrain advantage. Never fully conquered. Fast cavalry and poisoned weapons culturally notable. | AB8: Princes Pass, Boneway (only 2 land entries), Hellholt, Yronwood | AC8: Dorne has only 2 land entry points. Attackers entering through either pass suffer -2 combat rolls. Non-Dornish armies suffer desert attrition (+0.5 to effective winter_mult). Cannot be fully conquered—last 1-2 Dornish castles always generate insurgency. | AD8: Desert mercenaries and Rhoynar warriors for hire | AE8: Reach (border conflicts), Stormlands (Marches) | AF8: house_yronwood, house_dayne, house_fowler, house_uller, house_blackmont, house_jordayne | AG8: house_yronwood, house_dayne, house_fowler, house_uller, house_blackmont | AJ8: https://awoiaf.westeros.org/index.php/Dorne
A9: PARTIAL | B9: Claude | C9: Vale of Arryn | D9: house_arryn | E9: King of Mountain and Vale | F9: Valemen | G9: Vale Mountain Clans (Stone Crows, Moon Brothers, Burned Men, Black Ears, Painted Dogs), Sistermen | H9: Stone | I9: faith_of_the_seven | J9: unknown | K9: mountains | L9: coast | M9: 1.2 | N9: Harsh mountain winters. High altitude means early frost and snow. | O9: YES | P9: None major | Q9: High Road (only land route in/out) | R9: Mountains on all sides. Only land entry: Bloody Gate on High Road. | S9: Three Sisters (Sisterton) | T9: Grain, livestock, copper, tin, timber | U9: Grain, livestock, metals (copper, tin), timber | V9: Gulltown (only major port) | W9: Self-sufficient. Limited external trade. Gulltown provides maritime access. | X9: ~20,000 maximum; ~8,000 readily available | Y9: 1:4 heavily infantry-based, mountain terrain | Z9: weak | AA9: The Eyrie is the most impregnable castle in Westeros—cannot be taken by siege in summer. Mountain clan raiders harass the High Road. | AB9: Bloody Gate (only land entry), Gulltown (only major port) | AC9: Only land entry is the Bloody Gate—armies that don't control it cannot enter except by sea. The Eyrie cannot be besieged in summer—only starved out in winter. | AD9: Mountain clan mercenaries and clansmen for hire | AE9: North (War Across the Water / Three Sisters) | AF9: house_royce, house_waynwood, house_corbray, house_hunter, house_redfort, house_hardyng | AG9: house_royce, house_waynwood, house_corbray, house_hunter, house_redfort | AJ9: https://awoiaf.westeros.org/index.php/Vale_of_Arryn
A10: PARTIAL | B10: Claude | C10: Iron Islands | D10: house_greyjoy | E10: King of the Iron Islands | F10: Ironborn | G10: Island clans: Harlaw, Great Wyk, Old Wyk, Orkmont, Pyke island, Saltcliffe, Blacktyde | H10: Pyke | I10: drowned_god | J10: faith_of_the_seven | K10: island | L10: coast | M10: 1.0 | N10: Sea-based winters are harsh but mitigated by ocean currents. Wind and storms frequent. | O10: YES | P10: None | Q10: Sea lanes only | R10: All territory is islands—no land connections to mainland | S10: Pyke, Great Wyk, Old Wyk, Harlaw, Saltcliffe, Blacktyde, Orkmont, Lonely Light | T10: Iron, fish, raiding income, ships | U10: Iron, ships, mercenary services, raiding plunder | V10: Pyke (Lordsport), Harlaw, Ten Towers | W10: Historically poor in resources—'the iron price' raiding culture supplements income. Naval economy. | X10: ~15,000 maximum; ~8,000 readily available | Y10: 0:5 no cavalry, all naval/boarding troops | Z10: strong | AA10: Iron Fleet is among strongest in Westeros. Ironborn excel at naval warfare and coastal raids. Weak on land. | AB10: Pyke (only approach requires naval passage) | AC10: All Iron Islands castles are port castles. Ironborn armies cannot use land routes to attack mainland—fleet only. Raiding a coastal castle earns bonus gold equal to its Economy value. | AD10: Ironborn raiders and sell-swords for hire; mercenary ships | AE10: North (Theon/hostages), Riverlands (raiding targets), Reach (raiding targets) | AF10: house_harlaw, house_goodbrother, house_blacktyde, house_drumm, house_botley, house_merlyn | AG10: house_harlaw, house_goodbrother, house_blacktyde, house_drumm, house_botley | AJ10: https://awoiaf.westeros.org/index.php/Iron_Islands
A11: PARTIAL | B11: Claude | C11: Crownlands | D11: house_baratheon_kings_landing | E11: Lord of the Seven Kingdoms (Iron Throne) | F11: Crownlanders | G11: Crackclaw Point (semi-independent clans), King's Landing commons, nobility | H11: Waters | I11: faith_of_the_seven | J11: unknown | K11: coast | L11: plains | M11: 1.0 | N11: Moderate winters. Protected by coastal influences. | O11: YES | P11: Blackwater Rush (flows to King's Landing) | Q11: King's Road, Rose Road, Gold Road (all converge at King's Landing) | R11: Narrow Sea (east), all roads lead here making it militarily central | S11: Dragonstone island, Driftmark, Claw Isle | T11: Trade, taxation, royal treasury, port income | U11: All goods pass through King's Landing; re-export economy | V11: King's Landing (largest city), Dragonstone | W11: All three major roads of Westeros converge at King's Landing. Royal treasury generates income from all regions. | X11: ~20,000 maximum; ~10,000 readily available | Y11: 2:3 mixed forces, City Watch dominates | Z11: moderate | AA11: City Watch of King's Landing (Gold Cloaks) defend the capital. Dragonstone has natural fortress advantages. | AB11: King's Landing (road convergence), Dragonstone (Narrow Sea control) | AC11: Controlling King's Landing generates Crown Tax: +3 gold per production cycle from all regions you control. First house to hold King's Landing for 3 consecutive cycles triggers a win condition check. | AD11: King's Landing mercenaries and city hire-swords; organized companies | AE11: None initially; others may target King's Landing | AF11: house_velaryon, house_celtigar, house_rosby, house_stokeworth, house_bar_emmon, house_sunglass | AG11: house_velaryon, house_celtigar, house_rosby, house_stokeworth, house_bar_emmon | AJ11: https://awoiaf.westeros.org/index.php/Crownlands
